<?xml version="1.0" ?>
<!-- =================================================================================== -->
<!-- |    This document was autogenerated by xacro from /home/florent/devel/isae/install/share/ur_description/urdf/ur5_joint_limited_robot.urdf.xacro | -->
<!-- |    EDITING THIS FILE BY HAND IS NOT RECOMMENDED                                 | -->
<!-- =================================================================================== -->
<robot name="ur5" xmlns:xacro="http://www.ros.org/wiki/xacro">
  <link name="ur5_link0">
    <visual>
      <geometry>
        <mesh filename="package://ur_description/meshes/ur5/visual/base.dae"/>
      </geometry>
    </visual>
    <collision>
      <geometry>
        <mesh filename="package://ur_description/meshes/ur5/collision/base.stl"/>
      </geometry>
    </collision>
  </link>
  <link name="ur5_link1">
    <visual>
      <geometry>
        <mesh filename="package://ur_description/meshes/ur5/visual/shoulder.dae"/>
      </geometry>
    </visual>
    <collision>
      <geometry>
        <mesh filename="package://ur_description/meshes/ur5/collision/shoulder.stl"/>
      </geometry>
    </collision>
  </link>
  <joint name="ur5_joint1" type="revolute">
  <safety_controller k_position="100.0" k_velocity="40.0" soft_lower_limit="-2.8973" soft_upper_limit="2.8973" />
    <origin rpy="0.0 0.0 0.0" xyz="0.0 0.0 0.089159"/>
    <parent link="ur5_link0"/>
    <child link="ur5_link1"/>
    <axis xyz="0 0 1"/>
    <limit effort="150.0" lower="-3.14159265" upper="3.14159265" velocity="3.15"/>
  </joint>
  <link name="ur5_link2">
    <visual>
      <geometry>
        <mesh filename="package://ur_description/meshes/ur5/visual/upperarm.dae"/>
      </geometry>
    </visual>
    <collision>
      <geometry>
        <mesh filename="package://ur_description/meshes/ur5/collision/upperarm.stl"/>
      </geometry>
    </collision>
  </link>
  <joint name="ur5_joint2" type="revolute">
  <safety_controller k_position="100.0" k_velocity="40.0" soft_lower_limit="-2.8973" soft_upper_limit="2.8973" />
    <origin rpy="0.0 1.570796325 0.0" xyz="0.0 0.13585 0.0"/>
    <parent link="ur5_link1"/>
    <child link="ur5_link2"/>
    <axis xyz="0 1 0"/>
    <limit effort="150.0" lower="-3.14159265" upper="3.14159265" velocity="3.15"/>
  </joint>
  <link name="ur5_link3">
    <visual>
      <geometry>
        <mesh filename="package://ur_description/meshes/ur5/visual/forearm.dae"/>
      </geometry>
    </visual>
    <collision>
      <geometry>
        <mesh filename="package://ur_description/meshes/ur5/collision/forearm.stl"/>
      </geometry>
    </collision>
  </link>
  <joint name="ur5_joint3" type="revolute">
  <safety_controller k_position="100.0" k_velocity="40.0" soft_lower_limit="-2.8973" soft_upper_limit="2.8973" />
    <origin rpy="0.0 0.0 0.0" xyz="0.0 -0.1197 0.425"/>
    <parent link="ur5_link2"/>
    <child link="ur5_link3"/>
    <axis xyz="0 1 0"/>
    <limit effort="150.0" lower="-3.14159265" upper="3.14159265" velocity="3.15"/>
  </joint>
  <link name="ur5_link4">
    <visual>
      <geometry>
        <mesh filename="package://ur_description/meshes/ur5/visual/wrist1.dae"/>
      </geometry>
    </visual>
    <collision>
      <geometry>
        <mesh filename="package://ur_description/meshes/ur5/collision/wrist1.stl"/>
      </geometry>
    </collision>
  </link>
  <joint name="ur5_joint4" type="revolute">
  <safety_controller k_position="100.0" k_velocity="40.0" soft_lower_limit="-2.8973" soft_upper_limit="2.8973" />
    <origin rpy="0.0 1.570796325 0.0" xyz="0.0 0.0 0.39225"/>
    <parent link="ur5_link3"/>
    <child link="ur5_link4"/>
    <axis xyz="0 1 0"/>
    <limit effort="28.0" lower="-3.14159265" upper="3.14159265" velocity="3.2"/>
  </joint>
  <link name="ur5_link5">
    <visual>
      <geometry>
        <mesh filename="package://ur_description/meshes/ur5/visual/wrist2.dae"/>
      </geometry>
    </visual>
    <collision>
      <geometry>
        <mesh filename="package://ur_description/meshes/ur5/collision/wrist2.stl"/>
      </geometry>
    </collision>
  </link>
    <joint name="ur5_joint5" type="revolute">
  <safety_controller k_position="100.0" k_velocity="40.0" soft_lower_limit="-2.8973" soft_upper_limit="2.8973" />
    <origin rpy="0.0 0.0 0.0" xyz="0.0 0.093 0.0"/>
    <parent link="ur5_link4"/>
    <child link="ur5_link5"/>
    <axis xyz="0 0 1"/>
    <limit effort="28.0" lower="-3.14159265" upper="3.14159265" velocity="3.2"/>
  </joint>
  <link name="ur5_link6">
    <visual>
      <geometry>
        <mesh filename="package://ur_description/meshes/ur5/visual/wrist3.dae"/>
      </geometry>
    </visual>
    <collision>
      <geometry>
        <mesh filename="package://ur_description/meshes/ur5/collision/wrist3.stl"/>
      </geometry>
    </collision>
  </link>
    <joint name="ur5_joint6" type="revolute">
  <safety_controller k_position="100.0" k_velocity="40.0" soft_lower_limit="-2.8973" soft_upper_limit="2.8973" />
    <origin rpy="0.0 0.0 0.0" xyz="0.0 0.0 0.09465"/>
    <parent link="ur5_link5"/>
    <child link="ur5_link6"/>
    <axis xyz="0 1 0"/>
    <limit effort="28.0" lower="-3.14159265" upper="3.14159265" velocity="3.2"/>
  </joint>
     <link name="ur5_link7" />
    <joint name="ur5_joint7" type="fixed">
    <origin rpy="0.0 0.0 0" xyz="0.0 0 0.107"/>
    <parent link="ur5_link6"/>
    <child link="ur5_link7"/>
  </joint>
  <joint name="ur5_hand_joint" type="fixed">
        <parent link="ur5_link7" />
        <child link="ur5_hand" />
        <origin rpy="0 -1.570796325 -1.5" xyz="0 0.08 -0.1" />
    </joint>
    <link name="ur5_hand">
        <visual>
            <geometry>
                <mesh filename="package://ur_description/meshes/ur5/visual/hand.dae" />
            </geometry>
        </visual>
        <collision>
            <geometry>
                <mesh filename="package://ur_description/meshes/ur5/collision/hand.stl" />
            </geometry>
        </collision>
    </link>
    <link name="ur5_leftfinger">
        <visual>
            <geometry>
                <mesh filename="package://ur_description/meshes/ur5/visual/finger.dae" />
            </geometry>
        </visual>
        <collision>
            <geometry>
                <mesh filename="package://ur_description/meshes/ur5/collision/finger.stl" />
            </geometry>
        </collision>
    </link>
    <link name="ur5_rightfinger">
        <visual>
            <origin rpy="0 0 3.14159265359" xyz="0 0 0" />
            <geometry>
                <mesh filename="package://ur_description/meshes/ur5/visual/finger.dae" />
            </geometry>
        </visual>
        <collision>
            <origin rpy="0 0 3.14159265359" xyz="0 0 0" />
            <geometry>
                <mesh filename="package://ur_description/meshes/ur5/collision/finger.stl" />
            </geometry>
        </collision>
    </link>
    <joint name="ur5_finger_joint1" type="prismatic">
        <parent link="ur5_hand" />
        <child link="ur5_leftfinger" />
        <origin rpy="0 0 0" xyz="0 0 0.0584" />
        <axis xyz="0 1 0" />
        <limit effort="20" lower="0.0" upper="0.04" velocity="0.2" />
    </joint>
    <joint name="ur5_finger_joint2" type="prismatic">
        <parent link="ur5_hand" />
        <child link="ur5_rightfinger" />
        <origin rpy="0 0 0" xyz="0 0 0.0584" />
        <axis xyz="0 -1 0" />
        <limit effort="20" lower="0.0" upper="0.04" velocity="0.2" />
        <mimic joint="ur5_finger_joint1" />
    </joint>
</robot>
